Workbook
Name IQ_CH: 110000
Name IQ_CQ: 5000
Name IQ_CY: 10000
Name IQ_DAILY: 500000
Name IQ_FH: 100000
Name IQ_FQ: 500
Name IQ_FY: 1000
Name IQ_LTM: 2000
Name IQ_MONTH: 15000
Name IQ_NTM: 6000
Name IQ_WEEK: 50000
Name IQ_YTD: 3000

Sheet Dates
A1: Forecast Month - | D1: September 2020
A3: Table Beginning Year--- | D3: =YEAR(D1)-4 -> 2016
A5: Table Beginning Month--- | D5: =+D3*100+1 -> 201601
A7: Last Historical Month--- | D7: =IF(MONTH(D1)>1,100*YEAR(D1)+MONTH(D1)-1,100*(YEAR(D1)-1)+12) -> 202008
A10: Domestic Tables:
B11: AAAA_DATEX or AAAA_YEAR | C11: =+D5 -> 201601 | D11: =C11+1 -> 201602 | E11: =D11+1 -> 201603 | F11: =E11+1 -> 201604 | G11: =F11+1 -> 201605 | H11: =G11+1 -> 201606 | I11: =H11+1 -> 201607 | J11: =I11+1 -> 201608 | K11: =J11+1 -> 201609 | ... N11: =M11+1 -> 201612 | O11: =+C11+100 -> 201701 | P11: =O11+1 -> 201702 | Q11: =P11+1 -> 201703 | R11: =Q11+1 -> 201704 | S11: =R11+1 -> 201705 | T11: =S11+1 -> 201706 | U11: =T11+1 -> 201707 | V11: =U11+1 -> 201708 | W11: =V11+1 -> 201709 | ... Z11: =Y11+1 -> 201712 | AA11: =+O11+100 -> 201801 | AB11: =AA11+1 -> 201802 | AC11: =AB11+1 -> 201803 | AD11: =AC11+1 -> 201804 | AE11: =AD11+1 -> 201805 | AF11: =AE11+1 -> 201806 | AG11: =AF11+1 -> 201807 | AH11: =AG11+1 -> 201808 | AI11: =AH11+1 -> 201809 | ... AL11: =AK11+1 -> 201812 | AM11: =+AA11+100 -> 201901 | AN11: =AM11+1 -> 201902 | AO11: =AN11+1 -> 201903 | AP11: =AO11+1 -> 201904 | AQ11: =AP11+1 -> 201905 | AR11: =AQ11+1 -> 201906 | AS11: =AR11+1 -> 201907 | AT11: =AS11+1 -> 201908 | AU11: =AT11+1 -> 201909 | ... AX11: =AW11+1 -> 201912 | AY11: =+AM11+100 -> 202001 | AZ11: =AY11+1 -> 202002 | BA11: =AZ11+1 -> 202003 | BB11: =BA11+1 -> 202004 | BC11: =BB11+1 -> 202005 | BD11: =BC11+1 -> 202006 | BE11: =BD11+1 -> 202007 | BF11: =BE11+1 -> 202008 | BG11: =BF11+1 -> 202009 | ... BJ11: =BI11+1 -> 202012 | BK11: =+AY11+100 -> 202101 | BL11: =BK11+1 -> 202102 | BM11: =BL11+1 -> 202103 | BN11: =BM11+1 -> 202104 | BO11: =BN11+1 -> 202105 | BP11: =BO11+1 -> 202106 | BQ11: =BP11+1 -> 202107 | BR11: =BQ11+1 -> 202108 | BS11: =BR11+1 -> 202109 | ... BV11: =BU11+1 -> 202112
B12: Column | C12: 265 | D12: 266 | E12: 267 | F12: 268 | G12: 269 | H12: 270 | I12: 271 | J12: 272 | K12: 273 | L12: 274 | M12: 275 | N12: 276 | O12: 277 | P12: 278 | Q12: 279 | R12: 280 | S12: 281 | T12: 282 | U12: 283 | V12: 284 | W12: 285 | X12: 286 | Y12: 287 | Z12: 288 | AA12: 289 | AB12: 290 | AC12: 291 | AD12: 292 | AE12: 293 | AF12: 294 | AG12: 295 | AH12: 296 | AI12: 297 | AJ12: 298 | AK12: 299 | AL12: 300 | AM12: 301 | AN12: 302 | AO12: 303 | AP12: 304 | AQ12: 305 | AR12: 306 | AS12: 307 | AT12: 308 | AU12: 309 | AV12: 310 | AW12: 311 | AX12: 312 | AY12: 313 | AZ12: 314 | BA12: 315 | BB12: 316 | BC12: 317 | BD12: 318 | BE12: 319 | BF12: 320 | BG12: 321 | BH12: 322 | BI12: 323 | BJ12: 324 | BK12: 325 | BL12: 326 | BM12: 327 | BN12: 328 | BO12: 329 | BP12: 330 | BQ12: 331 | BR12: 332 | BS12: 333 | BT12: 334 | BU12: 335 | BV12: 336
B13: Historical | C13: =IF(C11<=$D$7,1,0) -> 1 | D13: =IF(D11<=$D$7,1,0) -> 1 | E13: =IF(E11<=$D$7,1,0) -> 1 | F13: =IF(F11<=$D$7,1,0) -> 1 | G13: =IF(G11<=$D$7,1,0) -> 1 | H13: =IF(H11<=$D$7,1,0) -> 1 | I13: =IF(I11<=$D$7,1,0) -> 1 | J13: =IF(J11<=$D$7,1,0) -> 1 | ... BV13: =IF(BV11<=$D$7,1,0) -> 0

Sheet Contents
B6: ="Short-Term Energy Outlook, "&Dates!D1 -> Short-Term Energy Outlook, September 2020
B8: Table 1. U.S. Energy Markets Summary
B9: Table 2. Energy Nominal Prices
B10: Table 3a. International Petroleum and Other Liquids Production, Consumption, and Inventories
B11: Table 3b. Non-OPEC Petroleum and Other Liquids Production
B12: Table 3c. OPEC Crude Oil (excluding Condensates) Production
B13: Table 3d. World Petroleum and Other Liquids Consumption
B14: Table 4a. U.S. Petroleum and Other Liquids Supply, Consumption, and Inventories
B15: Table 4b. U.S. Hydrocarbon Gas Liquids (HGL) and Petroleum Refinery Balances
B16: Table 4c. U.S. Regional Motor Gasoline Prices and Inventories
B17: Table 5a. U.S. Natural Gas Supply, Consumption, and Inventories
B18: Table 5b. U.S. Regional Natural Gas Prices
B19: Table 6. U.S. Coal Supply, Consumption, and Inventories
... B29: Table 9c. U.S. Regional Weather Data

Sheet 1tab
A1: Table of Contents | B1: Table 1. U.S. Energy Markets Summary
B2: ="U.S. Energy Information Administration | Short-Term Energy Outlook - "&Dates!D1 -> U.S. Energy Information Administration | Short-Term Energy Outlook - September 2020
C3: =Dates!D3 -> 2016 | O3: =C3+1 -> 2017 | AA3: =O3+1 -> 2018 | AM3: =AA3+1 -> 2019 | AY3: =AM3+1 -> 2020 | BK3: =AY3+1 -> 2021
C4: Jan | D4: Feb | E4: Mar | F4: Apr | G4: May | H4: Jun | I4: Jul | J4: Aug | K4: Sep | L4: Oct | M4: Nov | N4: Dec | O4: Jan | P4: Feb | Q4: Mar | R4: Apr | S4: May | T4: Jun | U4: Jul | V4: Aug | W4: Sep | X4: Oct | Y4: Nov | Z4: Dec | AA4: Jan | AB4: Feb | AC4: Mar | AD4: Apr | AE4: May | AF4: Jun | AG4: Jul | AH4: Aug | AI4: Sep | AJ4: Oct | AK4: Nov | AL4: Dec | AM4: Jan | AN4: Feb | AO4: Mar | AP4: Apr | AQ4: May | AR4: Jun | AS4: Jul | AT4: Aug | AU4: Sep | AV4: Oct | AW4: Nov | AX4: Dec | AY4: Jan | AZ4: Feb | BA4: Mar | BB4: Apr | BC4: May | BD4: Jun | BE4: Jul | BF4: Aug | BG4: Sep | BH4: Oct | BI4: Nov | BJ4: Dec | BK4: Jan | BL4: Feb | BM4: Mar | BN4: Apr | BO4: May | BP4: Jun | BQ4: Jul | BR4: Aug | BS4: Sep | BT4: Oct | BU4: Nov | BV4: Dec
B5: Energy Supply
BM6: .
B7: Crude Oil Production (a)
A8: COPRPUS | B8: (million barrels per day) | C8: 9.197118 | D8: 9.055534 | E8: 9.089036 | F8: 8.868831 | G8: 8.822702 | H8: 8.65412 | I8: 8.645738 | J8: 8.676224 | K8: 8.533839 | L8: 8.834121 | M8: 8.89748 | N8: 8.797784 | O8: 8.863309 | P8: 9.10269 | Q8: 9.1622 | R8: 9.10027 | S8: 9.182546 | T8: 9.10659 | U8: 9.23506 | V8: 9.248466 | W8: 9.511855 | X8: 9.65324 | Y8: 10.070655 | Z8: 9.973278 | AA8: 10.017673 | AB8: 10.281403 | AC8: 10.504038 | AD8: 10.510258 | AE8: 10.459527 | AF8: 10.649082 | AG8: 10.890996 | AH8: 11.360519 | AI8: 11.497683 | AJ8: 11.631364 | AK8: 11.999309 | AL8: 12.037536 | AM8: 11.865013 | AN8: 11.678834 | AO8: 11.937306 | AP8: 12.134698 | AQ8: 12.163192 | AR8: 12.087544 | AS8: 11.819095 | AT8: 12.424769 | AU8: 12.495187 | AV8: 12.672552 | AW8: 12.85978 | AX8: 12.802096 | AY8: 12.754821 | AZ8: 12.745602 | BA8: 12.737068 | BB8: 12.009977 | BC8: 10.016158 | BD8: 10.436196 | BE8: 10.737451 | BF8: 10.802894 | BG8: 11.20299 | BH8: 11.03722 | BI8: 11.13856 | BJ8: 11.05731 | BK8: 10.97068 | BL8: 10.88705 | BM8: 11.02336 | BN8: 10.98248 | BO8: 10.96094 | BP8: 10.96618 | BQ8: 10.98843 | BR8: 11.04953 | BS8: 11.20527 | BT8: 11.1585 | BU8: 11.367 | BV8: 11.43208
B10: Dry Natural Gas Production
A11: NGPRPUS | B11: (billion cubic feet per day) | C11: 73.559355 | D11: 74.601172 | E11: 73.75871 | F11: 73.707267 | G11: 72.867677 | H11: 72.169633 | I11: 72.760129 | J11: 72.183161 | K11: 71.705 | L11: 71.424032 | M11: 72.02 | N11: 71.208839 | O11: 70.562806 | P11: 71.549714 | Q11: 73.167871 | R11: 73.257767 | S11: 73.256548 | T11: 73.966667 | U11: 74.729484 | V11: 74.687452 | W11: 75.9937 | X11: 77.344 | Y11: 79.751233 | Z11: 79.278645 | AA11: 78.536484 | AB11: 80.224893 | AC11: 81.789065 | AD11: 81.296 | AE11: 82.055742 | AF11: 82.174033 | AG11: 82.936161 | AH11: 84.616581 | AI11: 86.883433 | AJ11: 87.033452 | AK11: 89.160967 | AL11: 88.741097 | AM11: 88.617387 | AN11: 89.412107 | AO11: 89.927806 | AP11: 90.404867 | AQ11: 89.92129 | AR11: 91.198467 | AS11: 91.277355 | AT11: 93.316032 | AU11: 94.389 | AV11: 95.781871 | AW11: 96.248533 | AX11: 95.876839 | AY11: 94.785613 | AZ11: 94.411379 | BA11: 94.248032 | BB11: 92.6432 | BC11: 87.571452 | BD11: 88.349333 | BE11: 88.86217 | BF11: 88.39126 | BG11: 88.06197 | BH11: 87.56469 | BI11: 87.30918 | BJ11: 86.56352 | BK11: 85.85995 | BL11: 85.49896 | BM11: 85.63702 | BN11: 85.60648 | BO11: 85.78392 | BP11: 86.21321 | BQ11: 86.55582 | BR11: 87.09051 | BS11: 87.56941 | BT11: 87.65786 | BU11: 87.88835 | BV11: 87.65101
B13: Coal Production
A14: CLPRPUS_TON | B14: (million short tons) | C14: 60.568715 | D14: 57.328506 | E14: 55.327888 | F14: 48.216355 | G14: 53.123077 | H14: 59.513341 | I14: 61.783814 | J14: 68.246998 | K14: 65.069717 | L14: 68.725231 | M14: 67.149752 | N14: 63.311104 | O14: 68.414386 | P14: 64.389031 | Q14: 64.335048 | R14: 58.753723 | S14: 62.115414 | T14: 66.228987 | U14: 62.966364 | V14: 70.58233 | W14: 62.891468 | X14: 66.367608 | Y14: 64.345233 | Z14: 63.219765 | AA14: 61.936683 | AB14: 60.235142 | AC14: 65.467142 | AD14: 58.032114 | AE14: 61.195975 | AF14: 61.557372 | AG14: 62.945246 | AH14: 69.301238 | AI14: 62.416694 | AJ14: 66.384385 | AK14: 62.717785 | AL14: 63.332764 | AM14: 65.732791 | AN14: 58.22357 | AO14: 55.58004 | AP14: 61.007259 | AQ14: 61.653404 | AR14: 56.515031 | AS14: 59.034596 | AT14: 63.75768 | AU14: 58.563501 | AV14: 57.142978 | AW14: 54.361009 | AX14: 53.699269 | AY14: 55.612462 | AZ14: 47.378792 | BA14: 46.060925 | BB14: 38.281796 | BC14: 36.346901 | BD14: 38.50618 | BE14: 43.086574 | BF14: 47.467762 | BG14: 30.41403 | BH14: 63.14259 | BI14: 40.25894 | BJ14: 24.63266 | BK14: 73.23193 | BL14: 46.80736 | BM14: 50.22003 | BN14: 37.69124 | BO14: 43.12436 | BP14: 42.99258 | BQ14: 52.07585 | BR14: 55.75175 | BS14: 46.75731 | BT14: 51.97425 | BU14: 47.21579 | BV14: 52.51854
B16: Energy Consumption
B18: Liquid Fuels
A19: PATCPUSX | B19: (million barrels per day) | C19: 19.062803 | D19: 19.846604 | E19: 19.728204 | F19: 19.340227 | G19: 19.328156 | H19: 19.846174 | I19: 19.77566 | J19: 20.274784 | K19: 19.756827 | L19: 19.650107 | M19: 19.658869 | N19: 19.983959 | O19: 19.322846 | P19: 19.190404 | Q19: 20.060124 | R19: 19.595325 | S19: 20.066245 | T19: 20.561246 | U19: 20.118924 | V19: 20.251193 | W19: 19.640611 | X19: 19.989651 | Y19: 20.307238 | Z19: 20.323455 | AA19: 20.54514 | AB19: 19.678705 | AC19: 20.756359 | AD19: 20.03652 | AE19: 20.247366 | AF19: 20.790269 | AG19: 20.682276 | AH19: 21.358391 | AI19: 20.082809 | AJ19: 20.734405 | AK19: 20.746512 | AL19: 20.303447 | AM19: 20.614983 | AN19: 20.283869 | AO19: 20.176247 | AP19: 20.3326 | AQ19: 20.387089 | AR19: 20.653979 | AS19: 20.734574 | AT19: 21.157914 | AU19: 20.248484 | AV19: 20.713987 | AW19: 20.736152 | AX19: 20.442869 | AY19: 19.905343 | AZ19: 19.83887 | BA19: 18.283773 | BB19: 14.690989 | BC19: 16.103228 | BD19: 17.435208 | BE19: 18.376966 | BF19: 18.654037 | BG19: 19.08705 | BH19: 19.53563 | BI19: 19.51591 | BJ19: 19.62895 | BK19: 19.36397 | BL19: 19.68637 | BM19: 19.7611 | BN19: 19.49877 | BO19: 19.79972 | BP19: 20.16091 | BQ19: 20.2778 | BR19: 20.71198 | BS19: 20.13744 | BT19: 20.49293 | BU19: 20.61759 | BV19: 20.20207
B21: Natural Gas
A22: NGTCPUS | B22: (billion cubic feet per day) | C22: 99.732097 | D22: 91.457241 | E22: 76.009613 | F22: 69.4616 | G22: 63.412839 | H22: 66.6885 | I22: 70.536 | J22: 71.237871 | K22: 64.925067 | L22: 62.103323 | M22: 71.981467 | N22: 92.460419 | O22: 94.005323 | P22: 83.592036 | Q22: 81.41 | R22: 64.416433 | S22: 61.047968 | T22: 63.6979 | U22: 69.100097 | V22: 67.557613 | W22: 64.031633 | X22: 65.548581 | Y22: 78.5892 | Z22: 99.499645 | AA22: 107.58 | AB22: 96.64025 | AC22: 90.084516 | AD22: 78.210533 | AE22: 66.157774 | AF22: 68.622233 | AG22: 75.631613 | AH22: 74.442097 | AI22: 71.7174 | AJ22: 73.519452 | AK22: 90.330733 | AL22: 96.551452 | AM22: 109.67034 | AN22: 107.1065 | AO22: 93.540726 | AP22: 73.365021 | AQ22: 68.416229 | AR22: 70.506187 | AS22: 77.651923 | AT22: 78.610013 | AU22: 73.871767 | AV22: 75.07375 | AW22: 91.760827 | AX22: 101.23745 | AY22: 106.08392 | AZ22: 104.65639 | BA22: 87.369845 | BB22: 74.920105 | BC22: 66.789305 | BD22: 71.12131 | BE22: 80.411412 | BF22: 75.834749 | BG22: 71.81988 | BH22: 71.77795 | BI22: 83.80008 | BJ22: 98.03057 | BK22: 102.4414 | BL22: 95.63975 | BM22: 84.58619 | BN22: 69.9565 | BO22: 63.29265 | BP22: 67.37492 | BQ22: 73.56347 | BR22: 72.90685 | BS22: 68.56315 | BT22: 70.75946 | BU22: 85.01188 | BV22: 96.40269
B24: Coal (b)
A25: CLTCPUS_TON | B25: (million short tons) | C25: 66.662224 | D25: 55.210717 | E25: 44.574606 | F25: 43.383704 | G25: 49.342933 | H25: 67.551229 | I25: 78.568539 | J25: 78.174537 | K25: 66.614898 | L25: 58.952703 | M25: 52.533242 | N25: 69.501358 | O25: 68.005594 | P25: 52.380924 | Q25: 53.325237 | R25: 48.565447 | S25: 55.201684 | T25: 63.098547 | U25: 74.213784 | V25: 70.22913 | W25: 59.039437 | X25: 54.435842 | Y25: 55.357275 | Z25: 63.002781 | AA25: 69.253774 | AB25: 50.024953 | AC25: 48.869909 | AD25: 44.793442 | AE25: 51.57359 | AF25: 60.239976 | AG25: 68.083151 | AH25: 67.97637 | AI25: 58.159414 | AJ25: 52.811207 | AK25: 56.170449 | AL25: 60.149091 | AM25: 60.219019 | AN25: 49.220423 | AO25: 48.417439 | AP25: 37.371611 | AQ25: 44.12901 | AR25: 48.353478 | AS25: 59.997894 | AT25: 56.467564 | AU25: 51.326178 | AV25: 41.404697 | AW25: 45.883513 | AX25: 44.552686 | AY25: 40.62428 | AZ25: 35.891931 | BA25: 32.729228 | BB25: 27.429269 | BC25: 30.409953 | BD25: 40.321093 | BE25: 52.184147 | BF25: 53.204089 | BG25: 42.84928 | BH25: 37.03536 | BI25: 38.21868 | BJ25: 44.24294 | BK25: 50.83467 | BL25: 40.64672 | BM25: 39.7936 | BN25: 35.41075 | BO25: 40.95408 | BP25: 48.21249 | BQ25: 58.17042 | BR25: 55.50806 | BS25: 43.83099 | BT25: 39.81175 | BU25: 35.15207 | BV25: 44.85997
B27: Electricity
A28: ESTXPUS | B28: (billion kilowatt hours per day) | C28: 10.735829 | D28: 10.616691 | E28: 9.5931623 | F28: 9.3472502 | G28: 9.5511918 | H28: 11.387909 | I28: 12.410947 | J28: 12.705332 | K28: 11.613767 | L28: 9.9364686 | M28: 9.6195099 | N28: 10.40155 | O28: 10.654882 | P28: 10.23951 | Q28: 9.7774315 | R28: 9.4671731 | S28: 9.7850943 | T28: 11.351136 | U28: 12.268893 | V28: 12.026143 | W28: 11.097418 | X28: 10.02787 | Y28: 9.8269714 | Z28: 10.475267 | AA28: 11.512331 | AB28: 10.848862 | AC28: 9.952281 | AD28: 9.6497108 | AE28: 10.160898 | AF28: 11.670347 | AG28: 12.516689 | AH28: 12.716431 | AI28: 11.642366 | AJ28: 10.354153 | AK28: 10.082795 | AL28: 10.470261 | AM28: 10.847718 | AN28: 10.797268 | AO28: 9.9658863 | AP28: 9.3424513 | AQ28: 9.7945466 | AR28: 10.928998 | AS28: 12.359918 | AT28: 12.24411 | AU28: 11.566641 | AV28: 10.143295 | AW28: 9.7969636 | AX28: 10.26451 | AY28: 10.405749 | AZ28: 10.42113 | BA28: 9.5826669 | BB28: 8.9637237 | BC28: 9.0794136 | BD28: 10.904585 | BE28: 12.51944 | BF28: 12.36575 | BG28: 11.07204 | BH28: 9.774687 | BI28: 9.520952 | BJ28: 10.01519 | BK28: 10.39851 | BL28: 10.3241 | BM28: 9.516555 | BN28: 9.130322 | BO28: 9.370148 | BP28: 11.17006 | BQ28: 12.07496 | BR28: 12.08199 | BS28: 11.16685 | BT28: 9.937416 | BU28: 9.640638 | BV28: 10.1305
B30: Renewables (c)
A31: RETCBUS | B31: (quadrillion Btu) | C31: 0.85459609 | D31: 0.85346212 | E31: 0.93013934 | F31: 0.88246185 | G31: 0.89627229 | H31: 0.85004286 | I31: 0.86806329 | J31: 0.81882543 | K31: 0.78510751 | L31: 0.82752041 | M31: 0.83070111 | N31: 0.93049417 | O31: 0.90214278 | P31: 0.85550178 | Q31: 1.0111207 | R31: 0.99001915 | S31: 1.0300484 | T31: 0.98706584 | U31: 0.91590969 | V31: 0.8609374 | W31: 0.83191795 | X31: 0.8859033 | Y31: 0.87183533 | Z31: 0.90106008 | AA31: 0.95129851 | AB31: 0.8898656 | AC31: 0.98994533 | AD31: 0.99671751 | AE31: 1.039604 | AF31: 1.0116174 | AG31: 0.9258135 | AH31: 0.93159787 | AI31: 0.84289605 | AJ31: 0.88002774 | AK31: 0.88377563 | AL31: 0.92037448 | AM31: 0.93815109 | AN31: 0.86931454 | AO31: 0.98966892 | AP31: 1.0205904 | AQ31: 1.0587459 | AR31: 0.99355423 | AS31: 0.97541678 | AT31: 0.93108061 | AU31: 0.88242492 | AV31: 0.92192805 | AW31: 0.91012745 | AX31: 0.949481 | AY31: 0.97015611 | AZ31: 0.97097396 | BA31: 0.96085656 | BB31: 0.90722291 | BC31: 1.0370478 | BD31: 1.055054 | BE31: 1.018402 | BF31: 0.9706454 | BG31: 0.9136654 | BH31: 0.9795106 | BI31: 0.9356283 | BJ31: 1.03843 | BK31: 1.062194 | BL31: 1.012385 | BM31: 1.111887 | BN31: 1.085563 | BO31: 1.147666 | BP31: 1.14946 | BQ31: 1.097835 | BR31: 1.062724 | BS31: 0.9923544 | BT31: 1.064873 | BU31: 1.005688 | BV31: 1.092342
B33: Total Energy Consumption (d)
A34: TETCFUEL | B34: (quadrillion Btu) | C34: 9.0531268 | D34: 8.2222882 | E34: 7.9754271 | F34: 7.4424836 | G34: 7.5720162 | H34: 7.9257457 | I34: 8.4589504 | J34: 8.5277539 | K34: 7.7366351 | L34: 7.6408437 | M34: 7.7031801 | N34: 9.0702154 | O34: 8.9744268 | P34: 7.6220622 | Q34: 8.4260467 | R34: 7.4450615 | S34: 7.7903388 | T34: 7.9541806 | U34: 8.4159791 | V34: 8.2839157 | W34: 7.6139454 | X34: 7.8044033 | Y34: 8.0912167 | Z34: 9.1813522 | AA34: 9.6511974 | AB34: 8.050959 | AC34: 8.6999258 | AD34: 7.876088 | AE34: 7.9718966 | AF34: 8.1350957 | AG34: 8.5988451 | AH34: 8.6766645 | AI34: 7.8495656 | AJ34: 8.0653704 | AK34: 8.4985736 | AL34: 9.0118497 | AM34: 9.5077797 | AN34: 8.3568339 | AO34: 8.6769682 | AP34: 7.6234312 | AQ34: 7.9082553 | AR34: 7.9027467 | AS34: 8.563315 | AT34: 8.5504368 | AU34: 7.8584574 | AV34: 7.9589366 | AW34: 8.3579336 | AX34: 8.9007682 | AY34: 8.951407 | AZ34: 8.3058003 | BA34: 7.838347 | BB34: 6.531408 | BC34: 6.8698474 | BD34: 7.202474 | BE34: 8.017686 | BF34: 7.886831 | BG34: 7.33865 | BH34: 7.496803 | BI34: 7.705793 | BJ34: 8.625698 | BK34: 8.875799 | BL34: 7.79855 | BM34: 8.140525 | BN34: 7.299328 | BO34: 7.54986 | BP34: 7.735818 | BQ34: 8.28118 | BR34: 8.248085 | BS34: 7.502939 | BT34: 7.738024 | BU34: 7.89336 | BV34: 8.704103
B36: Energy Prices
B38: Crude Oil West Texas Intermediate Spot
A39: WTIPUUS | B39: (dollars per barrel) | C39: 31.683 | D39: 30.323 | E39: 37.545 | F39: 40.754 | G39: 46.712 | H39: 48.757 | I39: 44.651 | J39: 44.724 | K39: 45.182 | L39: 49.775 | M39: 45.661 | N39: 51.972 | O39: 52.504 | P39: 53.468 | Q39: 49.328 | R39: 51.06 | S39: 48.476 | T39: 45.178 | U39: 46.63 | V39: 48.037 | W39: 49.822 | X39: 51.578 | Y39: 56.639 | Z39: 57.881 | AA39: 63.698 | AB39: 62.229 | AC39: 62.725 | AD39: 66.254 | AE39: 69.978 | AF39: 67.873 | AG39: 70.981 | AH39: 68.055 | AI39: 70.231 | AJ39: 70.749 | AK39: 56.963 | AL39: 49.523 | AM39: 51.376 | AN39: 54.954 | AO39: 58.151 | AP39: 63.862 | AQ39: 60.827 | AR39: 54.657 | AS39: 57.354 | AT39: 54.805 | AU39: 56.947 | AV39: 53.963 | AW39: 57.027 | AX39: 59.877 | AY39: 57.52 | AZ39: 50.54 | BA39: 29.21 | BB39: 16.55 | BC39: 28.56 | BD39: 38.31 | BE39: 40.71 | BF39: 42.34 | BG39: 41.5 | BH39: 41.5 | BI39: 41 | BJ39: 41 | BK39: 41 | BL39: 42 | BM39: 43 | BN39: 44 | BO39: 45 | BP39: 46 | BQ39: 46 | BR39: 46 | BS39: 46 | BT39: 47 | BU39: 47 | BV39: 47
B41: Natural Gas Henry Hub Spot
A42: NGHHUUS | B42: (dollars per million Btu) | C42: 2.283 | D42: 1.989 | E42: 1.729 | F42: 1.917 | G42: 1.922 | H42: 2.587 | I42: 2.822 | J42: 2.822 | K42: 2.992 | L42: 2.977 | M42: 2.548 | N42: 3.591 | O42: 3.304 | P42: 2.852 | Q42: 2.88 | R42: 3.103 | S42: 3.15 | T42: 2.975 | U42: 2.984 | V42: 2.9 | W42: 2.976 | X42: 2.879 | Y42: 3.014 | Z42: 2.821 | AA42: 3.69 | AB42: 2.67 | AC42: 2.693 | AD42: 2.796 | AE42: 2.8 | AF42: 2.967 | AG42: 2.833 | AH42: 2.961 | AI42: 2.995 | AJ42: 3.276 | AK42: 4.091 | AL42: 4.041 | AM42: 3.109 | AN42: 2.691 | AO42: 2.948 | AP42: 2.647 | AQ42: 2.638 | AR42: 2.399 | AS42: 2.366 | AT42: 2.221 | AU42: 2.559 | AV42: 2.331 | AW42: 2.653 | AX42: 2.219 | AY42: 2.02 | AZ42: 1.91 | BA42: 1.79 | BB42: 1.74 | BC42: 1.748 | BD42: 1.631 | BE42: 1.767 | BF42: 2.3 | BG42: 2.311643 | BH42: 2.521893 | BI42: 2.921351 | BJ42: 3.290992 | BK42: 3.40071 | BL42: 3.330532 | BM42: 3.250458 | BN42: 3.020415 | BO42: 3.009198 | BP42: 3.097928 | BQ42: 3.087371 | BR42: 3.139721 | BS42: 3.181556 | BT42: 3.2029 | BU42: 3.233813 | BV42: 3.284355
B44: Coal
A45: CLEUDUS | B45: (dollars per million Btu) | C45: 2.12 | D45: 2.11 | E45: 2.17 | F45: 2.16 | G45: 2.16 | H45: 2.1 | I45: 2.11 | J45: 2.11 | K45: 2.12 | L45: 2.07 | M45: 2.08 | N45: 2.08 | O45: 2.09 | P45: 2.06 | Q45: 2.07 | R45: 2.08 | S45: 2.09 | T45: 2.07 | U45: 2.06 | V45: 2.05 | W45: 2.02 | X45: 2.03 | Y45: 2.04 | Z45: 2.04 | AA45: 2.06 | AB45: 2.07 | AC45: 2.04 | AD45: 2.07 | AE45: 2.04 | AF45: 2.04 | AG45: 2.05 | AH45: 2.06 | AI45: 2.05 | AJ45: 2.04 | AK45: 2.06 | AL45: 2.11 | AM45: 2.1 | AN45: 2.07 | AO45: 2.08 | AP45: 2.07 | AQ45: 2.06 | AR45: 2.03 | AS45: 2.02 | AT45: 2 | AU45: 1.96 | AV45: 1.96 | AW45: 1.97 | AX45: 1.92 | AY45: 1.94 | AZ45: 1.91 | BA45: 1.94 | BB45: 1.93 | BC45: 1.886535 | BD45: 1.9005933 | BE45: 1.991536 | BF45: 1.999782 | BG45: 1.997256 | BH45: 2.017247 | BI45: 2.001649 | BJ45: 1.994013 | BK45: 2.051538 | BL45: 2.038602 | BM45: 2.044072 | BN45: 2.061034 | BO45: 2.055372 | BP45: 2.03002 | BQ45: 2.017288 | BR45: 2.027445 | BS45: 2.033408 | BT45: 2.029492 | BU45: 2.031119 | BV45: 2.037041
B47: Macroeconomic
B49: Real Gross Domestic Product
A50: GDPQXUS | B50: (billion chained 2012 dollars - SAAR) | C50: 17586.754 | D50: 17614.903 | E50: 17638.134 | F50: 17643.779 | G50: 17666.675 | H50: 17694.154 | I50: 17730.014 | J50: 17763.81 | K50: 17799.34 | L50: 17840.496 | M50: 17876.574 | N50: 17911.467 | O50: 17947.202 | P50: 17978.201 | Q50: 18006.493 | R50: 18020.345 | S50: 18052.021 | T50: 18089.79 | U50: 18135.521 | V50: 18184.073 | W50: 18237.314 | X50: 18301.907 | Y50: 18359.534 | Z50: 18416.856 | AA50: 18480.451 | AB50: 18532.229 | AC50: 18578.768 | AD50: 18616.924 | AE50: 18655.343 | AF50: 18690.882 | AG50: 18725.091 | AH50: 18753.703 | AI50: 18778.271 | AJ50: 18782.311 | AK50: 18811.151 | AL50: 18848.308 | AM50: 18914.676 | AN50: 18952.798 | AO50: 18983.568 | AP50: 18989.642 | AQ50: 19018.714 | AR50: 19053.441 | AS50: 19102.685 | AT50: 19142.075 | AU50: 19180.472 | AV50: 19269.195 | AW50: 19267.119 | AX50: 19225.563 | AY50: 19323.28 | AZ50: 19068.697 | BA50: 18640.567 | BB50: 18038.892 | BC50: 17263.671 | BD50: 16314.903 | BE50: 17932.212 | BF50: 18159.243 | BG50: 18304.57 | BH50: 18274.95 | BI50: 18326.83 | BJ50: 18366.96 | BK50: 18356.99 | BL50: 18402.37 | BM50: 18464.76 | BN50: 18575.05 | BO50: 18648.27 | BP50: 18715.31 | BQ50: 18766.55 | BR50: 18828.48 | BS50: 18891.47 | BT50: 18954.32 | BU50: 19020.32 | BV50: 19088.26
A51: GDPQXUS_PCT | B51: Percent change from prior year | C51: 1.9033277 | D51: 1.7764711 | E51: 1.651685 | F51: 1.4488308 | G51: 1.3878659 | H51: 1.3881749 | I51: 1.4873745 | J51: 1.5810751 | K51: 1.7071811 | L51: 1.9796512 | M51: 2.0851974 | N51: 2.1376998 | O51: 2.0495431 | P51: 2.0624474 | Q51: 2.0884225 | R51: 2.1342654 | S51: 2.1812019 | T51: 2.2359705 | U51: 2.28712 | V51: 2.3658359 | W51: 2.4606233 | X51: 2.5863095 | Y51: 2.7016331 | Z51: 2.8215954 | AA51: 2.97121 | AB51: 3.0816645 | AC51: 3.1781595 | AD51: 3.3105895 | AE51: 3.3421303 | AF51: 3.3228207 | AG51: 3.2509119 | AH51: 3.1325805 | AI51: 2.9662069 | AJ51: 2.6248844 | AK51: 2.4598495 | AL51: 2.342703 | AM51: 2.349641 | AN51: 2.2693896 | AO51: 2.1788272 | AP51: 2.0020374 | AQ51: 1.9478107 | AR51: 1.9397664 | AS51: 2.016516 | AT51: 2.0709053 | AU51: 2.1418432 | AV51: 2.5922494 | AW51: 2.4239276 | AX51: 2.0015325 | AY51: 2.1602497 | AZ51: 0.61151335 | BA51: -1.8068264 | BB51: -5.0066758 | BC51: -9.2279813 | BD51: -14.37293 | BE51: -6.1272698 | BF51: -5.1344061 | BG51: -4.566609 | BH51: -5.159783 | BI51: -4.880293 | BJ51: -4.465963 | BK51: -5.000647 | BL51: -3.494339 | BM51: -0.9431584 | BN51: 2.972231 | BO51: 8.020291 | BP51: 14.71299 | BQ51: 4.652711 | BR51: 3.685366 | BS51: 3.206255 | BT51: 3.71754 | BU51: 3.784032 | BV51: 3.927208
B53: GDP Implicit Price Deflator
A54: GDPDIUS | B54: (Index, 2012=100) | C54: 104.80544 | D54: 104.87511 | E54: 105.02544 | F54: 105.41541 | G54: 105.60785 | H54: 105.76174 | I54: 105.79322 | J54: 105.93289 | K54: 106.09689 | L54: 106.32359 | M54: 106.50748 | N54: 106.68693 | O54: 106.88385 | P54: 107.03796 | Q54: 107.17119 | R54: 107.2167 | S54: 107.35826 | T54: 107.52904 | U54: 107.75778 | V54: 107.96544 | W54: 108.18078 | X54: 108.41607 | Y54: 108.63752 | Z54: 108.85741 | AA54: 109.04137 | AB54: 109.28393 | AC54: 109.5507 | AD54: 109.92837 | AE54: 110.17859 | AF54: 110.38804 | AG54: 110.505 | AH54: 110.67167 | AI54: 110.83633 | AJ54: 111.01856 | AK54: 111.16456 | AL54: 111.29389 | AM54: 111.33307 | AN54: 111.48419 | AO54: 111.67374 | AP54: 111.99196 | AQ54: 112.19074 | AR54: 112.3603 | AS54: 112.4667 | AT54: 112.60326 | AU54: 112.73604 | AV54: 112.85941 | AW54: 112.98885 | AX54: 113.11874 | AY54: 113.38493 | AZ54: 113.41381 | BA54: 113.34126 | BB54: 113.16726 | BC54: 112.89181 | BD54: 112.51493 | BE54: 113.255 | BF54: 113.40433 | BG54: 113.5242 | BH54: 113.5575 | BI54: 113.6611 | BJ54: 113.7779 | BK54: 113.9417 | BL54: 114.0599 | BM54: 114.1661 | BN54: 114.2432 | BO54: 114.3383 | BP54: 114.4343 | BQ54: 114.531 | BR54: 114.629 | BS54: 114.7281 | BT54: 114.8352 | BU54: 114.9313 | BV54: 115.0233
A55: GDPDIUS_PCT | B55: Percent change from prior year | C55: 0.80296922 | D55: 0.81125988 | E55: 0.83062887 | F55: 0.87913428 | G55: 0.9067556 | H55: 0.93174551 | I55: 0.88302139 | J55: 0.95619707 | K55: 1.0800608 | L55: 1.3212499 | M55: 1.4968095 | N55: 1.6733024 | O55: 1.9831102 | P55: 2.0623119 | Q55: 2.0430675 | R55: 1.70876 | S55: 1.6574595 | T55: 1.6710166 | U55: 1.8569768 | V55: 1.91872 | W55: 1.9641376 | X55: 1.9680312 | Y55: 1.9998943 | Z55: 2.03444 | AA55: 2.0185636 | AB55: 2.0982863 | AC55: 2.2202969 | AD55: 2.5291457 | AE55: 2.6270297 | AF55: 2.6588167 | AG55: 2.5494422 | AH55: 2.5065633 | AI55: 2.4547388 | AJ55: 2.4004572 | AK55: 2.3261182 | AL55: 2.2382321 | AM55: 2.1016828 | AN55: 2.0133421 | AO55: 1.9379492 | AP55: 1.8772157 | AQ55: 1.8262605 | AR55: 1.7866603 | AS55: 1.7752171 | AT55: 1.7453361 | AU55: 1.713972 | AV55: 1.6581479 | AW55: 1.6410773 | AX55: 1.6396694 | AY55: 1.842985 | AZ55: 1.730855 | BA55: 1.4932056 | BB55: 1.049447 | BC55: 0.62489477 | BD55: 0.13761946 | BE55: 0.70091527 | BF55: 0.71141287 | BG55: 0.6990929 | BH55: 0.618531 | BI55: 0.5949489 | BJ55: 0.5827538 | BK55: 0.4910673 | BL55: 0.5696608 | BM55: 0.72774 | BN55: 0.9507232 | BO55: 1.281302 | BP55: 1.705914 | BQ55: 1.126687 | BR55: 1.079948 | BS55: 1.060535 | BT55: 1.125151 | BU55: 1.117517 | BV55: 1.094523
B57: Real Disposable Personal Income
...

Sheet 2tab
A1: Table of Contents | B1: Table 2. Energy Prices
B2: ="U.S. Energy Information Administration | Short-Term Energy Outlook - "&Dates!D1 -> U.S. Energy Information Administration | Short-Term Energy Outlook - September 2020
C3: =Dates!D3 -> 2016 | O3: =C3+1 -> 2017 | AA3: =O3+1 -> 2018 | AM3: =AA3+1 -> 2019 | AY3: =AM3+1 -> 2020 | BK3: =AY3+1 -> 2021
C4: Jan | D4: Feb | E4: Mar | F4: Apr | G4: May | H4: Jun | I4: Jul | J4: Aug | K4: Sep | L4: Oct | M4: Nov | N4: Dec | O4: Jan | P4: Feb | Q4: Mar | R4: Apr | S4: May | T4: Jun | U4: Jul | V4: Aug | W4: Sep | X4: Oct | Y4: Nov | Z4: Dec | AA4: Jan | AB4: Feb | AC4: Mar | AD4: Apr | AE4: May | AF4: Jun | AG4: Jul | AH4: Aug | AI4: Sep | AJ4: Oct | AK4: Nov | AL4: Dec | AM4: Jan | AN4: Feb | AO4: Mar | AP4: Apr | AQ4: May | AR4: Jun | AS4: Jul | AT4: Aug | AU4: Sep | AV4: Oct | AW4: Nov | AX4: Dec | AY4: Jan | AZ4: Feb | BA4: Mar | BB4: Apr | BC4: May | BD4: Jun | BE4: Jul | BF4: Aug | BG4: Sep | BH4: Oct | BI4: Nov | BJ4: Dec | BK4: Jan | BL4: Feb | BM4: Mar | BN4: Apr | BO4: May | BP4: Jun | BQ4: Jul | BR4: Aug | BS4: Sep | BT4: Oct | BU4: Nov | BV4: Dec
B5: Crude Oil (dollars per barrel)
A6: WTIPUUS | B6: West Texas Intermediate Spot Average | C6: 31.683 | D6: 30.323 | E6: 37.545 | F6: 40.754 | G6: 46.712 | H6: 48.757 | I6: 44.651 | J6: 44.724 | K6: 45.182 | L6: 49.775 | M6: 45.661 | N6: 51.972 | O6: 52.504 | P6: 53.468 | Q6: 49.328 | R6: 51.06 | S6: 48.476 | T6: 45.178 | U6: 46.63 | V6: 48.037 | W6: 49.822 | X6: 51.578 | Y6: 56.639 | Z6: 57.881 | AA6: 63.698 | AB6: 62.229 | AC6: 62.725 | AD6: 66.254 | AE6: 69.978 | AF6: 67.873 | AG6: 70.981 | AH6: 68.055 | AI6: 70.231 | AJ6: 70.749 | AK6: 56.963 | AL6: 49.523 | AM6: 51.376 | AN6: 54.954 | AO6: 58.151 | AP6: 63.862 | AQ6: 60.827 | AR6: 54.657 | AS6: 57.354 | AT6: 54.805 | AU6: 56.947 | AV6: 53.963 | AW6: 57.027 | AX6: 59.877 | AY6: 57.52 | AZ6: 50.54 | BA6: 29.21 | BB6: 16.55 | BC6: 28.56 | BD6: 38.31 | BE6: 40.71 | BF6: 42.34 | BG6: 41.5 | BH6: 41.5 | BI6: 41 | BJ6: 41 | BK6: 41 | BL6: 42 | BM6: 43 | BN6: 44 | BO6: 45 | BP6: 46 | BQ6: 46 | BR6: 46 | BS6: 46 | BT6: 47 | BU6: 47 | BV6: 47
A7: BREPUUS | B7: Brent Spot Average | C7: 30.7 | D7: 32.182 | E7: 38.21 | F7: 41.583 | G7: 46.742 | H7: 48.247 | I7: 44.952 | J7: 45.843 | K7: 46.568 | L7: 49.522 | M7: 44.734 | N7: 53.289 | O7: 54.577 | P7: 54.87 | Q7: 51.589 | R7: 52.308 | S7: 50.327 | T7: 46.368 | U7: 48.479 | V7: 51.704 | W7: 56.153 | X7: 57.508 | Y7: 62.714 | Z7: 64.374 | AA7: 69.077 | AB7: 65.318 | AC7: 66.017 | AD7: 72.106 | AE7: 76.975 | AF7: 74.405 | AG7: 74.254 | AH7: 72.528 | AI7: 78.891 | AJ7: 81.032 | AK7: 64.748 | AL7: 57.362 | AM7: 59.41 | AN7: 63.961 | AO7: 66.139 | AP7: 71.233 | AQ7: 71.318 | AR7: 64.221 | AS7: 63.919 | AT7: 59.042 | AU7: 62.827 | AV7: 59.713 | AW7: 63.212 | AX7: 67.31 | AY7: 63.65 | AZ7: 55.66 | BA7: 32.01 | BB7: 18.38 | BC7: 29.38 | BD7: 40.27 | BE7: 43.24 | BF7: 44.74 | BG7: 44 | BH7: 44 | BI7: 44 | BJ7: 44.5 | BK7: 45 | BL7: 46 | BM7: 47 | BN7: 48 | BO7: 49 | BP7: 50 | BQ7: 50 | BR7: 50 | BS7: 50 | BT7: 51 | BU7: 51 | BV7: 51
A8: RAIMUUS | B8: U.S. Imported Average | C8: 27.48 | D8: 26.66 | E8: 32.24 | F8: 35.9 | G8: 40.88 | H8: 44.13 | I8: 41.48 | J8: 41.21 | K8: 40.86 | L8: 44.76 | M8: 41.8 | N8: 46.72 | O8: 48.12 | P8: 49.38 | Q8: 46.53 | R8: 47.47 | S8: 47.21 | T8: 44.03 | U8: 44.76 | V8: 47.62 | W8: 50.46 | X8: 51.4 | Y8: 56.3 | Z8: 57.44 | AA8: 59.71 | AB8: 58.03 | AC8: 56.82 | AD8: 61.24 | AE8: 65.89 | AF8: 66.82 | AG8: 66.62 | AH8: 65.48 | AI8: 66.7 | AJ8: 67.79 | AK8: 54.4 | AL8: 42.8 | AM8: 49.71 | AN8: 56.66 | AO8: 61.14 | AP8: 65.42 | AQ8: 65.03 | AR8: 58.16 | AS8: 59.18 | AT8: 55.41 | AU8: 57.31 | AV8: 54.44 | AW8: 55.27 | AX8: 56.85 | AY8: 53.96 | AZ8: 47.42 | BA8: 28.5 | BB8: 16.74 | BC8: 22.43 | BD8: 37.31 | BE8: 39.71 | BF8: 40.84 | BG8: 39.75 | BH8: 39.5 | BI8: 38.85 | BJ8: 38.7 | BK8: 38.55 | BL8: 39.55 | BM8: 40.55 | BN8: 41.4 | BO8: 42.4 | BP8: 43.4 | BQ8: 43.25 | BR8: 43.25 | BS8: 43.25 | BT8: 44 | BU8: 44 | BV8: 44
A9: RACPUUS | B9: U.S. Refiner Average Acquisition Cost | C9: 29.99 | D9: 28.53 | E9: 33.82 | F9: 37.71 | G9: 42.88 | H9: 45.96 | I9: 43.26 | J9: 42.7 | K9: 42.73 | L9: 46.85 | M9: 44.06 | N9: 48.66 | O9: 49.99 | P9: 51.24 | Q9: 48.65 | R9: 49.47 | S9: 48.47 | T9: 45.25 | U9: 46.27 | V9: 48.22 | W9: 50.78 | X9: 52.67 | Y9: 57.75 | Z9: 59.53 | AA9: 63.25 | AB9: 61.74 | AC9: 60.81 | AD9: 64.41 | AE9: 68.91 | AF9: 68.35 | AG9: 70.29 | AH9: 67.68 | AI9: 69.29 | AJ9: 70.99 | AK9: 59.01 | AL9: 48.83 | AM9: 52.29 | AN9: 57.62 | AO9: 61.64 | AP9: 66.51 | AQ9: 65.11 | AR9: 59.16 | AS9: 60.53 | AT9: 56.9 | AU9: 58.6 | AV9: 55.85 | AW9: 57.88 | AX9: 60.27 | AY9: 57.94 | AZ9: 51.37 | BA9: 32.55 | BB9: 19.41 | BC9: 23.82 | BD9: 42.31 | BE9: 44.21 | BF9: 44.84 | BG9: 43.25 | BH9: 42.5 | BI9: 41.35 | BJ9: 40.7 | BK9: 40.05 | BL9: 41.05 | BM9: 42.05 | BN9: 42.4 | BO9: 43.4 | BP9: 44.4 | BQ9: 44.25 | BR9: 44.25 | BS9: 44.25 | BT9: 45 | BU9: 45 | BV9: 45
B10: U.S. Liquid Fuels (cents per gallon)
B11: Refiner Prices for Resale
A12: MGWHUUS | B12: Gasoline | C12: 118.7 | D12: 104.6 | E12: 133.5 | F12: 147.6 | G12: 161.3 | H12: 164.3 | I12: 149 | J12: 150.8 | K12: 151.4 | L12: 156.8 | M12: 142.7 | N12: 158.5 | O12: 162.7 | P12: 162.5 | Q12: 163.4 | R12: 172.3 | S12: 166.8 | T12: 157.4 | U12: 162.1 | V12: 171.1 | W12: 182.6 | X12: 173 | Y12: 180.6 | Z12: 172 | AA12: 184.9 | AB12: 182.3 | AC12: 188.9 | AD12: 205.4 | AE12: 220.5 | AF12: 213.5 | AG12: 214.8 | AH12: 211.8 | AI12: 213.6 | AJ12: 209 | AK12: 173.2 | AL12: 151.4 | AM12: 148.3 | AN12: 162.4 | AO12: 188.1 | AP12: 213.8 | AQ12: 211 | AR12: 190.9 | AS12: 198.4 | AT12: 182 | AU12: 185.4 | AV12: 187.1 | AW12: 181.9 | AX12: 175.7 | AY12: 174.3 | AZ12: 166.9 | BA12: 112.7 | BB12: 64.5 | BC12: 104.9 | BD12: 131.1 | BE12: 135.7264 | BF12: 135.357 | BG12: 134.3208 | BH12: 131.0109 | BI12: 129.6017 | BJ12: 125.6939 | BK12: 126.0864 | BL12: 134.0299 | BM12: 146.3235 | BN12: 157.4543 | BO12: 162.7729 | BP12: 163.9369 | BQ12: 161.9385 | BR12: 163.6528 | BS12: 156.8328 | BT12: 154.0468 | BU12: 149.6308 | BV12: 146.7825
A13: DSWHUUS | B13: Diesel Fuel | C13: 101.5 | D13: 104.3 | E13: 118.9 | F13: 125.1 | G13: 143.2 | H13: 153.1 | I13: 142.6 | J13: 144 | K13: 147.1 | L13: 159.2 | M13: 146.9 | N13: 160.6 | O13: 163.6 | P13: 164.1 | Q13: 158.1 | R13: 162.7 | S13: 155.2 | T13: 146.5 | U13: 153.3 | V13: 168.1 | W13: 184.7 | X13: 185.2 | Y13: 193.6 | Z13: 191.8 | AA13: 204.2 | AB13: 197.2 | AC13: 195.2 | AD13: 209.9 | AE13: 225.8 | AF13: 220.3 | AG13: 219.2 | AH13: 220.3 | AI13: 228.2 | AJ13: 237.9 | AK13: 213 | AL13: 179.4 | AM13: 178.9 | AN13: 195 | AO13: 202 | AP13: 210 | AQ13: 210.6 | AR13: 187.4 | AS13: 193.8 | AT13: 186.5 | AU13: 195.5 | AV13: 198.4 | AW13: 197.4 | AX13: 194.3 | AY13: 185.8 | AZ13: 167.1 | BA13: 127.8 | BB13: 90.8 | BC13: 87.8 | BD13: 113.5 | BE13: 125.7255 | BF13: 128.4926 | BG13: 129.7652 | BH13: 131.9414 | BI13: 133.8598 | BJ13: 134.9807 | BK13: 132.1109 | BL13: 138.2607 | BM13: 146.7593 | BN13: 149.9468 | BO13: 152.7527 | BP13: 157.5339 | BQ13: 156.5571 | BR13: 161.4472 | BS13: 160.3902 | BT13: 164.7735 | BU13: 163.5341 | BV13: 158.7916
A14: D2WHUUS | B14: Heating Oil | C14: 97.6 | D14: 94.8 | E14: 107 | F14: 111.3 | G14: 129.1 | H14: 140.4 | I14: 130.5 | J14: 130.7 | K14: 134.1 | L14: 144.3 | M14: 138.6 | N14: 150.7 | O14: 156 | P14: 155.3 | Q14: 149.5 | R14: 149.9 | S14: 144.7 | T14: 137.5 | U14: 139.2 | V14: 152.2 | W14: 166.8 | X14: 169.5 | Y14: 178.1 | Z14: 184.1 | AA14: 199 | AB14: 188.9 | AC14: 184.8 | AD14: 198.2 | AE14: 214.3 | AF14: 208.9 | AG14: 207.9 | AH14: 211.4 | AI14: 221.4 | AJ14: 228.1 | AK14: 209.8 | AL14: 179.6 | AM14: 181.3 | AN14: 190.7 | AO14: 195.8 | AP14: 199.3 | AQ14: 198.9 | AR14: 182.4 | AS14: 184.7 | AT14: 179.5 | AU14: 190.1 | AV14: 192.6 | AW14: 188.4 | AX14: 191.9 | AY14: 186.3 | AZ14: 162.7 | BA14: 123.8 | BB14: 87.2 | BC14: 79.5 | BD14: 100.5 | BE14: 112.0148 | BF14: 113.4807 | BG14: 116.324 | BH14: 119.3555 | BI14: 123.6607 | BJ14: 129.6065 | BK14: 135.318 | BL14: 141.7558 | BM14: 146.0648 | BN14: 145.2568 | BO14: 150.0935 | BP14: 153.9599 | BQ14: 153.3661 | BR14: 159.3821 | BS14: 159.2544 | BT14: 161.4806 | BU14: 161.598 | BV14: 161.358
B15: Refiner Prices to End Users
A16: JKTCUUS | B16: Jet Fuel | C16: 103.8 | D16: 103.2 | E16: 113.3 | F16: 118.7 | G16: 134.2 | H16: 146.4 | I16: 139.3 | J16: 133 | K16: 139.4 | L16: 150.6 | M16: 142.6 | N16: 153.9 | O16: 158.4 | P16: 161.5 | Q16: 155.4 | R16: 159.5 | S16: 149.2 | T16: 143.4 | U16: 147.8 | V16: 161.3 | W16: 179.5 | X16: 174.3 | Y16: 183.1 | Z16: 186.9 | AA16: 201.2 | AB16: 197 | AC16: 192.4 | AD16: 208 | AE16: 222.1 | AF16: 219.6 | AG16: 217.6 | AH16: 218.3 | AI16: 225.7 | AJ16: 234.9 | AK16: 216.2 | AL16: 185.2 | AM16: 182.7 | AN16: 195.6 | AO16: 200.5 | AP16: 206.3 | AQ16: 214.1 | AR16: 190.7 | AS16: 197.3 | AT16: 190.1 | AU16: 193.7 | AV16: 196.5 | AW16: 197.9 | AX16: 197.9 | AY16: 195.8 | AZ16: 166.7 | BA16: 125.7 | BB16: 74 | BC16: 72.8 | BD16: 104.6 | BE16: 115.6158 | BF16: 117.2477 | BG16: 119.4963 | BH16: 119.2729 | BI16: 121.6367 | BJ16: 123.9251 | BK16: 130.4892 | BL16: 132.0952 | BM16: 134.7895 | BN16: 136.9759 | BO16: 141.0557 | BP16: 145.9754 | BQ16: 147.6658 | BR16: 149.3801 | BS16: 152.1669 | BT16: 156.2153 | BU16: 155.2175 | BV16: 155.9437
A17: RFTCUUS | B17: No. 6 Residual Fuel Oil (a) | C17: 71 | D17: 63.2 | E17: 69.3 | F17: 78.2 | G17: 92.2 | H17: 98.3 | I17: 103 | J17: 99 | K17: 107.6 | L17: 111.5 | M17: 110.6 | N17: 123 | O17: 130.9 | P17: 129.1 | Q17: 123.9 | R17: 120.1 | S17: 121.3 | T17: 119.5 | U17: 121.1 | V17: 120.4 | W17: 131.4 | X17: 130.4 | Y17: 141.3 | Z17: 148.4 | AA17: 150.7 | AB17: 149 | AC17: 145.2 | AD17: 150.4 | AE17: 166.7 | AF17: 173.1 | AG17: 176.7 | AH17: 176.4 | AI17: 176.1 | AJ17: 187.5 | AK17: 182.7 | AL17: 160.8 | AM17: 142.5 | AN17: 156.8 | AO17: 163.9 | AP17: 168.5 | AQ17: 163.5 | AR17: 160.1 | AS17: 162.5 | AT17: 146.6 | AU17: 156 | AV17: 154.3 | AW17: 159.4 | AX17: 174.5 | AY17: 193.9 | AZ17: 173.5 | BA17: 137.1 | BB17: 97.6 | BC17: 81.7 | BD17: 113.9 | BE17: 129.8054 | BF17: 135.5618 | BG17: 141.4674 | BH17: 136.6559 | BI17: 134.5692 | BJ17: 136.4806 | BK17: 101.5597 | BL17: 103.9973 | BM17: 103.1752 | BN17: 101.8418 | BO17: 103.7211 | BP17: 105.4754 | BQ17: 102.9016 | BR17: 106.3433 | BS17: 105.1741 | BT17: 104.2278 | BU17: 106.9813 | BV17: 107.6167
B18: Retail Prices Including Taxes
A19: MGRARUS | B19: Gasoline Regular Grade (b) | C19: 194.85 | D19: 176.36 | E19: 196.875 | F19: 211.275 | G19: 226.82 | H19: 236.55 | I19: 223.9 | J19: 217.76 | K19: 221.85 | L19: 224.94 | M19: 218.15 | N19: 225.425 | O19: 234.9 | P19: 230.4 | Q19: 232.5 | R19: 241.725 | S19: 239.14 | T19: 234.65 | U19: 229.98 | V19: 238.025 | W19: 264.525 | X19: 250.5 | Y19: 256.35 | Z19: 247.675 | AA19: 255.46 | AB19: 258.725 | AC19: 259.125 | AD19: 275.7 | AE19: 290.075 | AF19: 289.075 | AG19: 284.86 | AH19: 283.575 | AI19: 283.55 | AJ19: 286 | AK19: 264.725 | AL19: 236.56 | AM19: 224.775 | AN19: 230.925 | AO19: 251.6 | AP19: 279.84 | AQ19: 285.925 | AR19: 271.575 | AS19: 274 | AT19: 262.1 | AU19: 259.22 | AV19: 262.7 | AW19: 259.775 | AX19: 255.5 | AY19: 254.775 | AZ19: 244.2 | BA19: 223.42 | BB19: 184.05 | BC19: 186.95 | BD19: 208.22 | BE19: 218.325 | BF19: 218.24 | BG19: 214.9041 | BH19: 209.4726 | BI19: 206.6344 | BJ19: 202.557 | BK19: 198.5024 | BL19: 204.0073 | BM19: 216.4063 | BN19: 231.1459 | BO19: 240.4855 | BP19: 242.6891 | BQ19: 240.8735 | BR19: 242.1785 | BS19: 233.2741 | BT19: 229.5019 | BU19: 227.4434 | BV19: 221.5425
A20: MGEIAUS | B20: Gasoline All Grades (b) | C20: 205.65 | D20: 187.2 | E20: 207.075 | F20: 221.575 | G20: 237.1 | H20: 246.7 | I20: 234.5 | J20: 228.38 | K20: 232.65 | L20: 235.92 | M20: 229.5 | N20: 236.55 | O20: 245.84 | P20: 241.6 | Q20: 243.675 | R20: 252.75 | S20: 250.26 | T20: 246.025 | U20: 241.44 | V20: 249.4 | W20: 276.125 | X20: 262.1 | Y20: 267.75 | Z20: 259.375 | AA20: 267.12 | AB20: 270.475 | AC20: 270.9 | AD20: 287.32 | AE20: 298.675 | AF20: 296.95 | AG20: 292.78 | AH20: 291.425 | AI20: 291.475 | AJ20: 294.26 | AK20: 273.575 | AL20: 245.72 | AM20: 233.75 | AN20: 239.325 | AO20: 259.425 | AP20: 288.12 | AQ20: 294.625 | AR20: 280.35 | AS20: 282.32 | AT20: 270.675 | AU20: 268.14 | AV20: 272.4 | AW20: 269.325 | AX20: 264.5 | AY20: 263.55 | AZ20: 253.25 | BA20: 232.9 | BB20: 193.825 | BC20: 196.05 | BD20: 216.96 | BE20: 227.2 | BF20: 227.22 | BG20: 225.2929 | BH20: 220.9097 | BI20: 218.7839 | BJ20: 215.2379 | BK20: 211.3081 | BL20: 216.9778 | BM20: 229.253 | BN20: 244.076 | BO20: 253.4818 | BP20: 255.5934 | BQ20: 253.9917 | BR20: 255.365 | BS20: 246.5758 | BT20: 243.003 | BU20: 241.1006 | BV20: 235.3729
A21: DSRTUUS | B21: On-highway Diesel Fuel | C21: 214.275 | D21: 199.82 | E21: 209 | F21: 215.15 | G21: 231.46 | H21: 242.25 | I21: 240.45 | J21: 235.06 | K21: 239.425 | L21: 245.44 | M21: 243.85 | N21: 251 | O21: 257.98 | P21: 256.8 | Q21: 255.35 | R21: 258.25 | S21: 256.04 | T21: 251.05 | U21: 249.64 | V21: 259.5 | W21: 278.475 | X21: 279.42 | Y21: 290.875 | Z21: 290.9 | AA21: 301.84 | AB21: 304.575 | AC21: 298.75 | AD21: 309.58 | AE21: 324.375 | AF21: 325.275 | AG21: 323.28 | AH21: 321.825 | AI21: 326.225 | AJ21: 336.54 | AK21: 329.95 | AL21: 312.28 | AM21: 297.975 | AN21: 299.65 | AO21: 307.625 | AP21: 312.1 | AQ21: 316.125 | AR21: 308.85 | AS21: 304.52 | AT21: 300.5 | AU21: 301.62 | AV21: 305.3 | AW21: 306.875 | AX21: 305.5 | AY21: 304.75 | AZ21: 290.95 | BA21: 272.86 | BB21: 249.3 | BC21: 239.225 | BD21: 240.8 | BE21: 243.375 | BF21: 242.92 | BG21: 239.4183 | BH21: 240.388 | BI21: 243.2138 | BJ21: 247.7026 | BK21: 245.8711 | BL21: 242.5339 | BM21: 245.6805 | BN21: 249.4638 | BO21: 252.5713 | BP21: 258.2394 | BQ21: 259.3264 | BR21: 262.1777 | BS21: 262.1294 | BT21: 265.1888 | BU21: 266.7515 | BV21: 267.8428
A22: D2RCAUS | B22: Heating Oil | C22: 197 | D22: 192.3 | E22: 194.7 | F22: 198.9 | G22: 209.7 | H22: 215.5 | I22: 213 | J22: 207.3 | K22: 212.2 | L22: 228.8 | M22: 225.6 | N22: 239.4 | O22: 248.2 | P22: 247.4 | Q22: 244.9 | R22: 243.8 | S22: 237.8 | T22: 228.4 | U22: 221.5 | V22: 229.2 | W22: 248.1 | X22: 252 | Y22: 263.3 | Z22: 270.3 | AA22: 290.2 | AB22: 285.6 | AC22: 282.7 | AD22: 287.5 | AE22: 313.2 | AF22: 313.2 | AG22: 322 | AH22: 322.9 | AI22: 327.9 | AJ22: 338.1 | AK22: 328.6 | AL22: 295.1 | AM22: 293.4 | AN22: 303 | AO22: 305 | AP22: 310.3 | AQ22: 303 | AR22: 294.6 | AS22: 293.2 | AT22: 287 | AU22: 289.4 | AV22: 300.8 | AW22: 298.4 | AX22: 303.5 | AY22: 305.2 | AZ22: 281.2 | BA22: 240.5 | BB22: 204.4 | BC22: 190.5 | BD22: 205.7 | BE22: 213.4 | BF22: 215.3406 | BG22: 220.8898 | BH22: 227.3887 | BI22: 234.6249 | BJ22: 243.4962 | BK22: 242.0145 | BL22: 245.8742 | BM22: 248.7853 | BN22: 246.2417 | BO22: 249.7531 | BP22: 251.0757 | BQ22: 250.062 | BR22: 255.6313 | BS22: 261.1271 | BT22: 267.3084 | BU22: 270.1148 | BV22: 274.2215
B23: Natural Gas
A24: NGHHMCF | B24: Henry Hub Spot (dollars per thousand cubic feet) | C24: 2.372037 | D24: 2.066571 | E24: 1.796431 | F24: 1.991763 | G24: 1.996958 | H24: 2.687893 | I24: 2.932058 | J24: 2.932058 | K24: 3.108688 | L24: 3.093103 | M24: 2.647372 | N24: 3.731049 | O24: 3.426248 | P24: 2.957524 | Q24: 2.98656 | R24: 3.217811 | S24: 3.26655 | T24: 3.085075 | U24: 3.094408 | V24: 3.0073 | W24: 3.086112 | X24: 2.985523 | Y24: 3.125518 | Z24: 2.925377 | AA24: 3.83022 | AB24: 2.77146 | AC24: 2.795334 | AD24: 2.902248 | AE24: 2.9064 | AF24: 3.079746 | AG24: 2.940654 | AH24: 3.073518 | AI24: 3.10881 | AJ24: 3.400488 | AK24: 4.246458 | AL24: 4.194558 | AM24: 3.230251 | AN24: 2.795949 | AO24: 3.062972 | AP24: 2.750233 | AQ24: 2.740882 | AR24: 2.492561 | AS24: 2.458274 | AT24: 2.307619 | AU24: 2.658801 | AV24: 2.421909 | AW24: 2.756467 | AX24: 2.305541 | AY24: 2.09878 | AZ24: 1.98449 | BA24: 1.85981 | BB24: 1.80786 | BC24: 1.816172 | BD24: 1.694609 | BE24: 1.835913 | BF24: 2.3897 | BG24: 2.401797 | BH24: 2.620247 | BI24: 3.035284 | BJ24: 3.419341 | BK24: 3.533338 | BL24: 3.460423 | BM24: 3.377226 | BN24: 3.138211 | BO24: 3.126557 | BP24: 3.218747 | BQ24: 3.207778 | BR24: 3.26217 | BS24: 3.305636 | BT24: 3.327813 | BU24: 3.359931 | BV24: 3.412445
A25: NGHHUUS | B25: Henry Hub Spot (dollars per million Btu) | C25: 2.283 | D25: 1.989 | E25: 1.729 | F25: 1.917 | G25: 1.922 | H25: 2.587 | I25: 2.822 | J25: 2.822 | K25: 2.992 | L25: 2.977 | M25: 2.548 | N25: 3.591 | O25: 3.304 | P25: 2.852 | Q25: 2.88 | R25: 3.103 | S25: 3.15 | T25: 2.975 | U25: 2.984 | V25: 2.9 | W25: 2.976 | X25: 2.879 | Y25: 3.014 | Z25: 2.821 | AA25: 3.69 | AB25: 2.67 | AC25: 2.693 | AD25: 2.796 | AE25: 2.8 | AF25: 2.967 | AG25: 2.833 | AH25: 2.961 | AI25: 2.995 | AJ25: 3.276 | AK25: 4.091 | AL25: 4.041 | AM25: 3.109 | AN25: 2.691 | AO25: 2.948 | AP25: 2.647 | AQ25: 2.638 | AR25: 2.399 | AS25: 2.366 | AT25: 2.221 | AU25: 2.559 | AV25: 2.331 | AW25: 2.653 | AX25: 2.219 | AY25: 2.02 | AZ25: 1.91 | BA25: 1.79 | BB25: 1.74 | BC25: 1.748 | BD25: 1.631 | BE25: 1.767 | BF25: 2.3 | BG25: 2.311643 | BH25: 2.521893 | BI25: 2.921351 | BJ25: 3.290992 | BK25: 3.40071 | BL25: 3.330532 | BM25: 3.250458 | BN25: 3.020415 | BO25: 3.009198 | BP25: 3.097928 | BQ25: 3.087371 | BR25: 3.139721 | BS25: 3.181556 | BT25: 3.2029 | BU25: 3.233813 | BV25: 3.284355
B26: U.S. Retail Prices (dollars per thousand cubic feet)
A27: NGICUUS | B27: Industrial Sector | C27: 3.62 | D27: 3.58 | E27: 3.02 | F27: 3 | G27: 2.9 | H27: 2.89 | I27: 3.57 | J27: 3.59 | K27: 3.74 | L27: 3.87 | M27: 3.86 | N27: 4.27 | O27: 4.85 | P27: 4.53 | Q27: 3.92 | R27: 4.11 | S27: 4.02 | T27: 4.05 | U27: 3.92 | V27: 3.78 | W27: 3.83 | X27: 3.78 | Y27: 3.84 | Z27: 4.19 | AA27: 4.48 | AB27: 4.87 | AC27: 4.02 | AD27: 3.91 | AE27: 3.81 | AF27: 3.78 | AG27: 3.77 | AH27: 3.68 | AI27: 3.76 | AJ27: 4.04 | AK27: 4.52 | AL27: 5.48 | AM27: 5.03 | AN27: 4.64 | AO27: 4.32 | AP27: 4 | AQ27: 3.64 | AR27: 3.55 | AS27: 3.34 | AT27: 3.2 | AU27: 3.35 | AV27: 3.43 | AW27: 3.87 | AX27: 3.88 | AY27: 3.66 | AZ27: 3.54 | BA27: 3.35 | BB27: 2.97 | BC27: 2.87 | BD27: 2.72 | BE27: 2.625402 | BF27: 2.981341 | BG27: 3.221986 | BH27: 3.473242 | BI27: 3.867312 | BJ27: 4.499436 | BK27: 4.846898 | BL27: 4.782888 | BM27: 4.608937 | BN27: 4.255328 | BO27: 4.053365 | BP27: 4.024722 | BQ27: 4.059366 | BR27: 4.118597 | BS27: 4.125163 | BT27: 4.343233 | BU27: 4.482456 | BV27: 4.800441
A28: NGCCUUS | B28: Commercial Sector | C28: 6.75 | D28: 6.86 | E28: 7.08 | F28: 6.98 | G28: 7.32 | H28: 7.72 | I28: 8.14 | J28: 8.3 | K28: 8.28 | L28: 7.96 | M28: 7.67 | N28: 7.27 | O28: 7.58 | P28: 7.89 | Q28: 7.68 | R28: 8.04 | S28: 8.31 | T28: 8.75 | U28: 8.81 | V28: 8.76 | W28: 8.52 | X28: 7.97 | Y28: 7.51 | Z28: 7.42 | AA28: 7.39 | AB28: 7.74 | AC28: 7.71 | AD28: 7.65 | AE28: 8.34 | AF28: 8.58 | AG28: 8.84 | AH28: 8.69 | AI28: 8.57 | AJ28: 7.69 | AK28: 7.34 | AL28: 7.7 | AM28: 7.7 | AN28: 7.58 | AO28: 7.44 | AP28: 7.76 | AQ28: 8.08 | AR28: 8.22 | AS28: 8.45 | AT28: 8.41 | AU28: 8.33 | AV28: 7.63 | AW28: 7.03 | AX28: 7.21 | AY28: 7.26 | AZ28: 7.06 | BA28: 7.32 | BB28: 7.38 | BC28: 7.75 | BD28: 8.17 | BE28: 8.03469 | BF28: 7.981679 | BG28: 7.849481 | BH28: 7.467032 | BI28: 7.282092 | BJ28: 7.345679 | BK28: 7.472415 | BL28: 7.588316 | BM28: 7.838334 | BN28: 7.998285 | BO28: 8.308761 | BP28: 8.635459 | BQ28: 8.725142 | BR28: 8.785313 | BS28: 8.638025 | BT28: 8.258414 | BU28: 8.011071 | BV28: 7.934739
A29: NGRCUUS | B29: Residential Sector | C29: 8.28 | D29: 8.36 | E29: 9.19 | F29: 9.65 | G29: 11.62 | H29: 14.43 | I29: 16.56 | J29: 17.6 | K29: 16.78 | L29: 13.74 | M29: 10.77 | N29: 9.06 | O29: 9.32 | P29: 10.01 | Q29: 9.86 | R29: 11.34 | S29: 13.25 | T29: 16.06 | U29: 17.86 | V29: 18.22 | W29: 16.92 | X29: 13.39 | Y29: 10.14 | Z29: 9.29 | AA29: 8.9 | AB29: 9.63 | AC29: 9.76 | AD29: 10.05 | AE29: 13.52 | AF29: 16.47 | AG29: 17.84 | AH29: 18.56 | AI29: 17.23 | AJ29: 12.23 | AK29: 9.41 | AL29: 9.61 | AM29: 9.45 | AN29: 9.47 | AO29: 9.49 | AP29: 10.94 | AQ29: 12.88 | AR29: 15.72 | AS29: 17.94 | AT29: 18.58 | AU29: 17.81 | AV29: 12.62 | AW29: 9.42 | AX29: 9.38 | AY29: 9.52 | AZ29: 9.26 | BA29: 9.86 | BB29: 10.68 | BC29: 11.85 | BD29: 15.37 | BE29: 16.67696 | BF29: 17.19186 | BG29: 16.19855 | BH29: 12.89145 | BI29: 10.25787 | BJ29: 9.465509 | BK29: 9.350119 | BL29: 9.63156 | BM29: 10.12503 | BN29: 11.15575 | BO29: 13.25461 | BP29: 15.82988 | BQ29: 17.35218 | BR29: 17.95393 | BS29: 16.93523 | BT29: 13.52284 | BU29: 10.87746 | BV29: 10.00708
B30: U.S. Electricity
B31: Power Generation Fuel Costs (dollars per million Btu)
A32: CLEUDUS | B32: Coal | C32: 2.12 | D32: 2.11 | E32: 2.17 | F32: 2.16 | G32: 2.16 | H32: 2.1 | I32: 2.11 | J32: 2.11 | K32: 2.12 | L32: 2.07 | M32: 2.08 | N32: 2.08 | O32: 2.09 | P32: 2.06 | Q32: 2.07 | R32: 2.08 | S32: 2.09 | T32: 2.07 | U32: 2.06 | V32: 2.05 | W32: 2.02 | X32: 2.03 | Y32: 2.04 | Z32: 2.04 | AA32: 2.06 | AB32: 2.07 | AC32: 2.04 | AD32: 2.07 | AE32: 2.04 | AF32: 2.04 | AG32: 2.05 | AH32: 2.06 | AI32: 2.05 | AJ32: 2.04 | AK32: 2.06 | AL32: 2.11 | AM32: 2.1 | AN32: 2.07 | AO32: 2.08 | AP32: 2.07 | AQ32: 2.06 | AR32: 2.03 | AS32: 2.02 | AT32: 2 | AU32: 1.96 | AV32: 1.96 | AW32: 1.97 | AX32: 1.92 | AY32: 1.94 | AZ32: 1.91 | BA32: 1.94 | BB32: 1.93 | BC32: 1.886535 | BD32: 1.9005933 | BE32: 1.991536 | BF32: 1.999782 | BG32: 1.997256 | BH32: 2.017247 | BI32: 2.001649 | BJ32: 1.994013 | BK32: 2.051538 | BL32: 2.038602 | BM32: 2.044072 | BN32: 2.061034 | BO32: 2.055372 | BP32: 2.03002 | BQ32: 2.017288 | BR32: 2.027445 | BS32: 2.033408 | BT32: 2.029492 | BU32: 2.031119 | BV32: 2.037041
A33: NGEUDUS | B33: Natural Gas | C33: 3.02 | D33: 2.7 | E33: 2.23 | F33: 2.42 | G33: 2.39 | H33: 2.67 | I33: 2.97 | J33: 2.95 | K33: 3.07 | L33: 3.13 | M33: 3.02 | N33: 3.96 | O33: 4.11 | P33: 3.56 | Q33: 3.35 | R33: 3.38 | S33: 3.48 | T33: 3.29 | U33: 3.21 | V33: 3.13 | W33: 3.16 | X33: 3.13 | Y33: 3.35 | Z33: 3.63 | AA33: 5.06 | AB33: 3.61 | AC33: 3.18 | AD33: 3.14 | AE33: 3.06 | AF33: 3.13 | AG33: 3.23 | AH33: 3.28 | AI33: 3.12 | AJ33: 3.43 | AK33: 4.18 | AL33: 4.72 | AM33: 4.01 | AN33: 3.64 | AO33: 3.45 | AP33: 2.89 | AQ33: 2.77 | AR33: 2.59 | AS33: 2.53 | AT33: 2.41 | AU33: 2.59 | AV33: 2.49 | AW33: 2.96 | AX33: 2.92 | AY33: 2.62 | AZ33: 2.4 | BA33: 2.14 | BB33: 2.1 | BC33: 2.1840616 | BD33: 2.0236668 | BE33: 2.020019 | BF33: 2.564614 | BG33: 2.53422 | BH33: 2.755428 | BI33: 3.257186 | BJ33: 3.839623 | BK33: 4.151144 | BL33: 4.024062 | BM33: 3.728754 | BN33: 3.382997 | BO33: 3.312859 | BP33: 3.300474 | BQ33: 3.309526 | BR33: 3.37085 | BS33: 3.379599 | BT33: 3.467066 | BU33: 3.565251 | BV33: 3.842569
A34: RFEUDUS | B34: Residual Fuel Oil (c) | C34: 7.08 | D34: 5.77 | E34: 5.63 | F34: 7.53 | G34: 9.07 | H34: 8.93 | I34: 11.72 | J34: 8.55 | K34: 8.42 | L34: 8.75 | M34: 9.03 | N34: 9.65 | O34: 11.25 | P34: 10.77 | Q34: 11.42 | R34: 10.64 | S34: 10.69 | T34: 10.48 | U34: 9.99 | V34: 10.03 | W34: 10.06 | X34: 10.61 | Y34: 10.28 | Z34: 13.6 | AA34: 11.45 | AB34: 11.46 | AC34: 12.1 | AD34: 12.2 | AE34: 12.83 | AF34: 13.81 | AG34: 13.76 | AH34: 14.38 | AI34: 13.91 | AJ34: 14.52 | AK34: 15.25 | AL34: 13.56 | AM34: 11.29 | AN34: 12.27 | AO34: 13.68 | AP34: 13.89 | AQ34: 13.47 | AR34: 12.92 | AS34: 12.93 | AT34: 13.72 | AU34: 11.53 | AV34: 12.65 | AW34: 12.04 | AX34: 12.84 | AY34: 13.15 | AZ34: 12.68 | BA34: 10.29 | BB34: 8.19 | BC34: 5.69 | BD34: 6.516473 | BE34: 7.227302 | BF34: 7.536568 | BG34: 7.757675 | BH34: 7.817229 | BI34: 7.934366 | BJ34: 8.500971 | BK34: 8.664829 | BL34: 8.486355 | BM34: 9.036337 | BN34: 9.883935 | BO34: 9.641691 | BP34: 10.20923 | BQ34: 9.900563 | BR34: 9.608057 | BS34: 9.414628 | BT34: 9.36891 | BU34: 9.451193 | BV34: 9.909358
A35: DKEUDUS | B35: Distillate Fuel Oil | C35: 8.9 | D35: 8.78 | E35: 9.46 | F35: 9.97 | G35: 10.76 | H35: 12.22 | I35: 12.08 | J35: 11.41 | K35: 11.29 | L35: 12.04 | M35: 12.01 | N35: 12.22 | O35: 13.02 | P35: 12.98 | Q35: 12.35 | R35: 13 | S35: 12.22 | T35: 11.56 | U35: 11.82 | V35: 12.95 | W35: 14.52 | X35: 14.11 | Y35: 14.61 | Z35: 14.63 | AA35: 16.07 | AB35: 15.19 | AC35: 15.02 | AD35: 16.19 | AE35: 16.73 | AF35: 16.59 | AG35: 16.21 | AH35: 16.93 | AI35: 17.39 | AJ35: 17.76 | AK35: 16.39 | AL35: 14.54 | AM35: 14.12 | AN35: 15.12 | AO35: 15.7 | AP35: 16.38 | AQ35: 16.18 | AR35: 14.87 | AS35: 15.1 | AT35: 14.83 | AU35: 15.11 | AV35: 15.38 | AW35: 15.29 | AX35: 14.63 | AY35: 14.57 | AZ35: 13.81 | BA35: 10.81 | BB35: 8.86 | BC35: 7.38 | BD35: 8.841579 | BE35: 9.97592 | BF35: 10.02393 | BG35: 10.06891 | BH35: 10.29216 | BI35: 10.85788 | BJ35: 10.80814 | BK35: 10.61384 | BL35: 10.98766 | BM35: 11.7483 | BN35: 11.84824 | BO35: 11.88585 | BP35: 12.40618 | BQ35: 12.55577 | BR35: 12.50336 | BS35: 12.38192 | BT35: 12.6899 | BU35: 13.09456 | BV35: 12.67188
B36: Retail Prices (cents per kilowatthour)
A37: ESICUUS | B37: Industrial Sector | C37: 6.44 | D37: 6.42 | E37: 6.46 | F37: 6.44 | G37: 6.57 | H37: 7.03 | I37: 7.23 | J37: 7.23 | K37: 7.14 | L37: 6.73 | M37: 6.66 | N37: 6.67 | O37: 6.59 | P37: 6.63 | Q37: 6.71 | R37: 6.6 | S37: 6.78 | T37: 7.19 | U37: 7.31 | V37: 7.22 | W37: 7.17 | X37: 6.91 | Y37: 6.73 | Z37: 6.54 | AA37: 6.94 | AB37: 6.78 | AC37: 6.63 | AD37: 6.57 | AE37: 6.79 | AF37: 7.17 | AG37: 7.32 | AH37: 7.25 | AI37: 7.05 | AJ37: 6.87 | AK37: 6.85 | AL37: 6.67 | AM37: 6.58 | AN37: 6.69 | AO37: 6.72 | AP37: 6.52 | AQ37: 6.7 | AR37: 6.91 | AS37: 7.19 | AT37: 7.45 | AU37: 7.1 | AV37: 6.86 | AW37: 6.73 | AX37: 6.37 | AY37: 6.33 | AZ37: 6.42 | BA37: 6.4 | BB37: 6.41 | BC37: 6.48 | BD37: 6.95 | BE37: 7.212112 | BF37: 7.482901 | BG37: 7.037383 | BH37: 6.884271 | BI37: 6.749302 | BJ37: 6.431784 | BK37: 6.428897 | BL37: 6.53088 | BM37: 6.505131 | BN37: 6.506512 | BO37: 6.60216 | BP37: 7.078125 | BQ37: 7.280569 | BR37: 7.426071 | BS37: 7.071047 | BT37: 6.903015 | BU37: 6.744802 | BV37: 6.44308
A38: ESCMUUS | B38: Commercial Sector | C38: 10.08 | D38: 10.25 | E38: 10.23 | F38: 10.19 | G38: 10.31 | H38: 10.66 | I38: 10.68 | J38: 10.76 | K38: 10.77 | L38: 10.55 | M38: 10.32 | N38: 10.17 | O38: 10.21 | P38: 10.48 | Q38: 10.46 | R38: 10.4 | S38: 10.59 | T38: 11.01 | U38: 10.97 | V38: 11.01 | W38: 11.03 | X38: 10.78 | Y38: 10.49 | Z38: 10.28 | AA38: 10.49 | AB38: 10.65 | AC38: 10.51 | AD38: 10.46 | AE38: 10.51 | AF38: 10.84 | AG38: 11 | AH38: 11.03 | AI38: 10.72 | AJ38: 10.77 | AK38: 10.54 | AL38: 10.33 | AM38: 10.3 | AN38: 10.54 | AO38: 10.45 | AP38: 10.51 | AQ38: 10.51 | AR38: 10.88 | AS38: 11.01 | AT38: 11.01 | AU38: 10.97 | AV38: 10.74 | AW38: 10.52 | AX38: 10.31 | AY38: 10.28 | AZ38: 10.36 | BA38: 10.41 | BB38: 10.42 | BC38: 10.44 | BD38: 10.96 | BE38: 10.80305 | BF38: 10.76138 | BG38: 10.80964 | BH38: 10.5908 | BI38: 10.38025 | BJ38: 10.17888 | BK38: 10.1845 | BL38: 10.3124 | BM38: 10.41576 | BN38: 10.5344 | BO38: 10.57425 | BP38: 11.13115 | BQ38: 11.02619 | BR38: 10.99741 | BS38: 11.03775 | BT38: 10.80215 | BU38: 10.57121 | BV38: 10.33799
A39: ESRCUUS | B39: Residential Sector | C39: 11.99 | D39: 12.14 | E39: 12.56 | F39: 12.43 | G39: 12.79 | H39: 12.73 | I39: 12.68 | J39: 12.88 | K39: 12.87 | L39: 12.46 | M39: 12.75 | N39: 12.23 | O39: 12.21 | P39: 12.79 | Q39: 12.89 | R39: 12.72 | S39: 13.07 | T39: 13.2 | U39: 13.08 | V39: 13.15 | W39: 13.28 | X39: 12.8 | Y39: 12.94 | Z39: 12.45 | AA39: 12.22 | AB39: 12.63 | AC39: 12.97 | AD39: 12.88 | AE39: 13.12 | AF39: 13.03 | AG39: 13.13 | AH39: 13.26 | AI39: 13.01 | AJ39: 12.85 | AK39: 12.9 | AL39: 12.43 | AM39: 12.48 | AN39: 12.73 | AO39: 12.86 | AP39: 13.29 | AQ39: 13.34 | AR39: 13.36 | AS39: 13.29 | AT39: 13.33 | AU39: 13.18 | AV39: 12.84 | AW39: 13.04 | AX39: 12.69 | AY39: 12.79 | AZ39: 12.85 | BA39: 13.08 | BB39: 13.28 | BC39: 13.14 | BD39: 13.28 | BE39: 13.18318 | BF39: 13.26825 | BG39: 13.36334 | BH39: 12.81881 | BI39: 13.07624 | BJ39: 12.66483 | BK39: 12.66208 | BL39: 12.81089 | BM39: 13.11731 | BN39: 13.47882 | BO39: 13.24509 | BP39: 13.36896 | BQ39: 13.39149 | BR39: 13.49265 | BS39: 13.61229 | BT39: 13.06284 | BU39: 13.40932 | BV39: 12.98724
B41: - = no data available
...

Sheet 3atab
A1: Table of Contents | B1: Table 3a. International Petroleum and Other Liquids Production, Consumption, and Inventories
B2: ="U.S. Energy Information Administration | Short-Term Energy Outlook - "&Dates!D1 -> U.S. Energy Information Administration | Short-Term Energy Outlook - September 2020
C3: =Dates!D3 -> 2016 | O3: =C3+1 -> 2017 | AA3: =O3+1 -> 2018 | AM3: =AA3+1 -> 2019 | AY3: =AM3+1 -> 2020 | BK3: =AY3+1 -> 2021
C4: Jan | D4: Feb | E4: Mar | F4: Apr | G4: May | H4: Jun | I4: Jul | J4: Aug | K4: Sep | L4: Oct | M4: Nov | N4: Dec | O4: Jan | P4: Feb | Q4: Mar | R4: Apr | S4: May | T4: Jun | U4: Jul | V4: Aug | W4: Sep | X4: Oct | Y4: Nov | Z4: Dec | AA4: Jan | AB4: Feb | AC4: Mar | AD4: Apr | AE4: May | AF4: Jun | AG4: Jul | AH4: Aug | AI4: Sep | AJ4: Oct | AK4: Nov | AL4: Dec | AM4: Jan | AN4: Feb | AO4: Mar | AP4: Apr | AQ4: May | AR4: Jun | AS4: Jul | AT4: Aug | AU4: Sep | AV4: Oct | AW4: Nov | AX4: Dec | AY4: Jan | AZ4: Feb | BA4: Mar | BB4: Apr | BC4: May | BD4: Jun | BE4: Jul | BF4: Aug | BG4: Sep | BH4: Oct | BI4: Nov | BJ4: Dec | BK4: Jan | BL4: Feb | BM4: Mar | BN4: Apr | BO4: May | BP4: Jun | BQ4: Jul | BR4: Aug | BS4: Sep | BT4: Oct | BU4: Nov | BV4: Dec
B5: Supply (million barrels per day) (a)
A6: papr_oecd | B6: OECD | C6: 27.543587 | D6: 27.212896 | E6: 27.285907 | F6: 26.696975 | G6: 26.131313 | H6: 26.015339 | I6: 27.074129 | J6: 26.703112 | K6: 26.119818 | L6: 26.996459 | M6: 27.699167 | N6: 27.046255 | O6: 27.14319 | P6: 27.61218 | Q6: 27.638727 | R6: 27.045682 | S6: 27.238509 | T6: 27.200005 | U6: 27.656536 | V6: 27.576236 | W6: 27.143804 | X6: 28.127776 | Y6: 28.98705 | Z6: 28.553756 | AA6: 28.835358 | AB6: 29.283587 | AC6: 29.587888 | AD6: 29.425531 | AE6: 29.246747 | AF6: 29.542648 | AG6: 30.284109 | AH6: 31.023603 | AI6: 30.450237 | AJ6: 31.118159 | AK6: 31.624212 | AL6: 31.735354 | AM6: 30.947444 | AN6: 30.953019 | AO6: 31.276847 | AP6: 31.557327 | AQ6: 31.29025 | AR6: 31.124839 | AS6: 31.066045 | AT6: 31.64805 | AU6: 31.730906 | AV6: 32.150029 | AW6: 32.967588 | AX6: 33.154992 | AY6: 33.029911 | AZ6: 32.809307 | BA6: 32.879805 | BB6: 30.760905 | BC6: 28.203264 | BD6: 29.028286 | BE6: 29.644886 | BF6: 29.671165 | BG6: 29.785757 | BH6: 30.373456 | BI6: 30.793183 | BJ6: 30.805767 | BK6: 30.525431 | BL6: 30.531601 | BM6: 30.848332 | BN6: 30.711949 | BO6: 30.8151 | BP6: 30.926322 | BQ6: 30.956763 | BR6: 31.129286 | BS6: 31.136407 | BT6: 31.573287 | BU6: 31.919023 | BV6: 31.85886
A7: papr_us | B7: U.S. (50 States) | C7: 14.997486 | D7: 14.832426 | E7: 15.039595 | F7: 14.860723 | G7: 15.026268 | H7: 14.810833 | I7: 14.843715 | J7: 14.641618 | K7: 14.456935 | L7: 14.807328 | M7: 14.994869 | N7: 14.733833 | O7: 14.764672 | P7: 15.174662 | Q7: 15.359209 | R7: 15.271164 | S7: 15.478991 | T7: 15.497487 | U7: 15.559018 | V7: 15.573718 | W7: 15.626286 | X7: 16.177258 | Y7: 16.818532 | Z7: 16.519238 | AA7: 16.397915 | AB7: 16.826144 | AC7: 17.243445 | AD7: 17.319088 | AE7: 17.368304 | AF7: 17.591205 | AG7: 17.967666 | AH7: 18.64216 | AI7: 18.702794 | AJ7: 18.739716 | AK7: 19.160769 | AL7: 19.201911 | AM7: 18.864001 | AN7: 18.727576 | AO7: 18.996404 | AP7: 19.321884 | AQ7: 19.408767 | AR7: 19.328356 | AS7: 18.957562 | AT7: 19.625607 | AU7: 19.764463 | AV7: 19.989586 | AW7: 20.328145 | AX7: 20.299549 | AY7: 20.417558 | AZ7: 19.997954 | BA7: 20.233452 | BB7: 18.574152 | BC7: 16.548511 | BD7: 17.654889 | BE7: 17.999049 | BF7: 18.156163 | BG7: 18.572031 | BH7: 18.502948 | BI7: 18.734051 | BJ7: 18.639566 | BK7: 18.383303 | BL7: 18.349143 | BM7: 18.600095 | BN7: 18.675494 | BO7: 18.772113 | BP7: 18.720137 | BQ7: 18.718822 | BR7: 18.895345 | BS7: 19.037942 | BT7: 18.978626 | BU7: 19.295059 | BV7: 19.275114
A8: papr_ca | B8: Canada | C8: 4.817274 | D8: 4.737274 | E8: 4.657274 | F8: 4.319274 | G8: 3.681274 | H8: 3.982274 | I8: 4.607274 | J8: 4.745274 | K8: 4.749274 | L8: 4.813274 | M8: 5.135274 | N8: 4.918274 | O8: 5.120139 | P8: 5.140139 | Q8: 4.910139 | R8: 4.500139 | S8: 4.633139 | T8: 4.686139 | U8: 4.963139 | V8: 5.117139 | W8: 4.933139 | X8: 4.945139 | Y8: 5.273139 | Z8: 5.350139 | AA8: 5.234139 | AB8: 5.395139 | AC8: 5.434139 | AD8: 5.068139 | AE8: 5.219139 | AF8: 5.147139 | AG8: 5.361139 | AH8: 5.647139 | AI8: 5.224139 | AJ8: 5.540139 | AK8: 5.637139 | AL8: 5.667139 | AM8: 5.392139 | AN8: 5.413139 | AO8: 5.498139 | AP8: 5.542139 | AQ8: 5.367139 | AR8: 5.504139 | AS8: 5.500139 | AT8: 5.527139 | AU8: 5.384139 | AV8: 5.455139 | AW8: 5.648139 | AX8: 5.793139 | AY8: 5.601139 | AZ8: 5.717139 | BA8: 5.636139 | BB8: 5.015139 | BC8: 4.747139 | BD8: 4.7390909 | BE8: 4.8247232 | BF8: 4.8536774 | BG8: 4.7766991 | BH8: 5.1081234 | BI8: 5.3160279 | BJ8: 5.4329926 | BK8: 5.3785152 | BL8: 5.3582219 | BM8: 5.4187207 | BN8: 5.4215615 | BO8: 5.4917305 | BP8: 5.5085196 | BQ8: 5.479853 | BR8: 5.5167075 | BS8: 5.5521593 | BT8: 5.7488301 | BU8: 5.759875 | BV8: 5.7069472
A9: papr_mx | B9: Mexico | C9: 2.604221 | D9: 2.541221 | E9: 2.533221 | F9: 2.504221 | G9: 2.502221 | H9: 2.526221 | I9: 2.502221 | J9: 2.490221 | K9: 2.441221 | L9: 2.418221 | M9: 2.395221 | N9: 2.355221 | O9: 2.341504 | P9: 2.348504 | Q9: 2.344504 | R9: 2.329504 | S9: 2.334504 | T9: 2.323504 | U9: 2.295504 | V9: 2.220504 | W9: 2.016504 | X9: 2.187504 | Y9: 2.133504 | Z9: 2.134504 | AA9: 2.203504 | AB9: 2.166504 | AC9: 2.129504 | AD9: 2.162504 | AE9: 2.127504 | AF9: 2.109504 | AG9: 2.106504 | AH9: 2.072504 | AI9: 2.081504 | AJ9: 1.983504 | AK9: 1.932504 | AL9: 1.944504 | AM9: 1.861504 | AN9: 1.942504 | AO9: 1.935504 | AP9: 1.915504 | AQ9: 1.899504 | AR9: 1.903504 | AS9: 1.900504 | AT9: 1.928504 | AU9: 1.956504 | AV9: 1.902504 | AW9: 1.939504 | AX9: 1.955504 | AY9: 1.995504 | AZ9: 1.997504 | BA9: 2.014504 | BB9: 2.000504 | BC9: 1.914504 | BD9: 1.9058496 | BE9: 1.879364 | BF9: 1.8016117 | BG9: 1.7898139 | BH9: 1.7783908 | BI9: 1.7720594 | BJ9: 1.772308 | BK9: 1.78316 | BL9: 1.8008988 | BM9: 1.8121056 | BN9: 1.8120407 | BO9: 1.8121131 | BP9: 1.783984 | BQ9: 1.7726502 | BR9: 1.7613026 | BS9: 1.7500115 | BT9: 1.7498424 | BU9: 1.7500484 | BV9: 1.7501338
